-------------------Log----------------24/04/17-11:17:44
Traceback (most recent call last):
  File "C:\inetpub\wwwroot\WEB_DATA_API\products.py", line 744, in get_manual_scan_data
    area_scan = request.json['areaScan']
                ~~~~~~~~~~~~^^^^^^^^^^^^
KeyError: 'areaScan'
 ---- scanqr_data