-------------------Log----------------24/04/23-08:37:08
Traceback (most recent call last):
  File "C:\inetpub\wwwroot\WEB_DATA_API\users.py", line 141, in login
    if not check_exist(username):
           ^^^^^^^^^^^^^^^^^^^^^
  File "C:\inetpub\wwwroot\WEB_DATA_API\users.py", line 20, in check_exist
    conn = pyodbc.connect('Driver={SQL Server}; Server=192.168.8.21; uid=sa; pwd=1234; Database=QC; Trusted_Connection=No;', timeout=1)
           ^^^^^^^^^^^^^^^^^^^^^^^^^^^^^^^^^^^^^^^^^^^^^^^^^^^^^^^^^^^^^^^^^^^^^^^^^^^^^^^^^^^^^^^^^^^^^^^^^^^^^^^^^^^^^^^^^^^^^^^^^^^^
pyodbc.OperationalError: ('HYT00', '[HYT00] [Microsoft][ODBC SQL Server Driver]Login timeout expired (0) (SQLDriverConnect)')
 ---- login
-------------------Log----------------24/04/23-08:56:56
Traceback (most recent call last):
  File "C:\inetpub\wwwroot\WEB_DATA_API\chemical.py", line 29, in get_file_names
    conn = pyodbc.connect('Driver={SQL Server}; Server=192.168.8.21; uid=sa; pwd=1234;Database=SPC; Trusted_Connection=No;',timeout=1)
           ^^^^^^^^^^^^^^^^^^^^^^^^^^^^^^^^^^^^^^^^^^^^^^^^^^^^^^^^^^^^^^^^^^^^^^^^^^^^^^^^^^^^^^^^^^^^^^^^^^^^^^^^^^^^^^^^^^^^^^^^^^^
pyodbc.OperationalError: ('HYT00', '[HYT00] [Microsoft][ODBC SQL Server Driver]Login timeout expired (0) (SQLDriverConnect)')

During handling of the above exception, another exception occurred:

Traceback (most recent call last):
  File "C:\inetpub\wwwroot\WEB_DATA_API\auth_middleware.py", line 50, in decorated
    return func(*args, **kwargs)
           ^^^^^^^^^^^^^^^^^^^^^
  File "C:\inetpub\wwwroot\WEB_DATA_API\chemical.py", line 65, in get_file_names
    Systemp_log(traceback.format_exc(), "file_names").append_new_line()
    ^^^^^^^^^^^^^^^^^^^^^^^^^^^^^^^^^^^^^^^^^^^^^^^^^
TypeError: Systemp_log.__init__() takes 2 positional arguments but 3 were given
 ---- token_required
-------------------Log----------------24/04/23-09:06:19
Traceback (most recent call last):
  File "C:\inetpub\wwwroot\WEB_DATA_API\CMM.py", line 162, in get_data
    conn = pyodbc.connect('Driver={SQL Server}; Server=192.168.8.21; uid=sa; pwd=1234;Database=QC; Trusted_Connection=No;',timeout=1)
           ^^^^^^^^^^^^^^^^^^^^^^^^^^^^^^^^^^^^^^^^^^^^^^^^^^^^^^^^^^^^^^^^^^^^^^^^^^^^^^^^^^^^^^^^^^^^^^^^^^^^^^^^^^^^^^^^^^^^^^^^^^
pyodbc.OperationalError: ('HYT00', '[HYT00] [Microsoft][ODBC SQL Server Driver]Login timeout expired (0) (SQLDriverConnect)')

During handling of the above exception, another exception occurred:

Traceback (most recent call last):
  File "C:\inetpub\wwwroot\WEB_DATA_API\auth_middleware.py", line 50, in decorated
    return func(*args, **kwargs)
           ^^^^^^^^^^^^^^^^^^^^^
  File "C:\inetpub\wwwroot\WEB_DATA_API\CMM.py", line 234, in get_data
    Systemp_log(traceback.format_exc(), "cmm_data").append_new_line()
    ^^^^^^^^^^^^^^^^^^^^^^^^^^^^^^^^^^^^^^^^^^^^^^^
TypeError: Systemp_log.__init__() takes 2 positional arguments but 3 were given
 ---- token_required
-------------------Log----------------24/04/23-09:06:20
Traceback (most recent call last):
  File "C:\inetpub\wwwroot\WEB_DATA_API\CMM.py", line 162, in get_data
    conn = pyodbc.connect('Driver={SQL Server}; Server=192.168.8.21; uid=sa; pwd=1234;Database=QC; Trusted_Connection=No;',timeout=1)
           ^^^^^^^^^^^^^^^^^^^^^^^^^^^^^^^^^^^^^^^^^^^^^^^^^^^^^^^^^^^^^^^^^^^^^^^^^^^^^^^^^^^^^^^^^^^^^^^^^^^^^^^^^^^^^^^^^^^^^^^^^^
pyodbc.OperationalError: ('HYT00', '[HYT00] [Microsoft][ODBC SQL Server Driver]Login timeout expired (0) (SQLDriverConnect)')

During handling of the above exception, another exception occurred:

Traceback (most recent call last):
  File "C:\inetpub\wwwroot\WEB_DATA_API\auth_middleware.py", line 50, in decorated
    return func(*args, **kwargs)
           ^^^^^^^^^^^^^^^^^^^^^
  File "C:\inetpub\wwwroot\WEB_DATA_API\CMM.py", line 234, in get_data
    Systemp_log(traceback.format_exc(), "cmm_data").append_new_line()
    ^^^^^^^^^^^^^^^^^^^^^^^^^^^^^^^^^^^^^^^^^^^^^^^
TypeError: Systemp_log.__init__() takes 2 positional arguments but 3 were given
 ---- token_required
-------------------Log----------------24/04/23-09:08:22
Traceback (most recent call last):
  File "C:\inetpub\wwwroot\WEB_DATA_API\CMM.py", line 72, in get_machines
    conn = pyodbc.connect('Driver={SQL Server}; Server=192.168.8.21; uid=sa; pwd=1234;Database=QC; Trusted_Connection=No;',timeout=1)
           ^^^^^^^^^^^^^^^^^^^^^^^^^^^^^^^^^^^^^^^^^^^^^^^^^^^^^^^^^^^^^^^^^^^^^^^^^^^^^^^^^^^^^^^^^^^^^^^^^^^^^^^^^^^^^^^^^^^^^^^^^^
pyodbc.OperationalError: ('HYT00', '[HYT00] [Microsoft][ODBC SQL Server Driver]Login timeout expired (0) (SQLDriverConnect)')

During handling of the above exception, another exception occurred:

Traceback (most recent call last):
  File "C:\inetpub\wwwroot\WEB_DATA_API\auth_middleware.py", line 50, in decorated
    return func(*args, **kwargs)
           ^^^^^^^^^^^^^^^^^^^^^
  File "C:\inetpub\wwwroot\WEB_DATA_API\CMM.py", line 108, in get_machines
    Systemp_log(traceback.format_exc(), "machines").append_new_line()
    ^^^^^^^^^^^^^^^^^^^^^^^^^^^^^^^^^^^^^^^^^^^^^^^
TypeError: Systemp_log.__init__() takes 2 positional arguments but 3 were given
 ---- token_required
-------------------Log----------------24/04/23-09:26:52
Traceback (most recent call last):
  File "C:\inetpub\wwwroot\WEB_DATA_API\products.py", line 1775, in search_data_1
    conn = pyodbc.connect('Driver={SQL Server}; Server=192.168.8.21; uid=sa; pwd=1234;Database=QC; Trusted_Connection=No;',timeout=1)
           ^^^^^^^^^^^^^^^^^^^^^^^^^^^^^^^^^^^^^^^^^^^^^^^^^^^^^^^^^^^^^^^^^^^^^^^^^^^^^^^^^^^^^^^^^^^^^^^^^^^^^^^^^^^^^^^^^^^^^^^^^^
pyodbc.OperationalError: ('HYT00', '[HYT00] [Microsoft][ODBC SQL Server Driver]Login timeout expired (0) (SQLDriverConnect)')
 ---- search_data_1
-------------------Log----------------24/04/23-10:01:34
Traceback (most recent call last):
  File "C:\inetpub\wwwroot\WEB_DATA_API\products.py", line 597, in get_scanqr_data
    conn = pyodbc.connect('Driver={SQL Server}; Server=192.168.8.21; uid=sa; pwd=1234; Database=Auto; Trusted_Connection=No;', timeout=1)
           ^^^^^^^^^^^^^^^^^^^^^^^^^^^^^^^^^^^^^^^^^^^^^^^^^^^^^^^^^^^^^^^^^^^^^^^^^^^^^^^^^^^^^^^^^^^^^^^^^^^^^^^^^^^^^^^^^^^^^^^^^^^^^^
pyodbc.OperationalError: ('HYT00', '[HYT00] [Microsoft][ODBC SQL Server Driver]Login timeout expired (0) (SQLDriverConnect)')

During handling of the above exception, another exception occurred:

Traceback (most recent call last):
  File "C:\inetpub\wwwroot\WEB_DATA_API\auth_middleware.py", line 50, in decorated
    return func(*args, **kwargs)
           ^^^^^^^^^^^^^^^^^^^^^
  File "C:\inetpub\wwwroot\WEB_DATA_API\products.py", line 682, in get_scanqr_data
    Systemp_log(traceback.format_exc(), "scanqr_data").append_new_line()
    ^^^^^^^^^^^^^^^^^^^^^^^^^^^^^^^^^^^^^^^^^^^^^^^^^^
TypeError: Systemp_log.__init__() takes 2 positional arguments but 3 were given
 ---- token_required
-------------------Log----------------24/04/23-11:09:41
Traceback (most recent call last):
  File "C:\inetpub\wwwroot\WEB_DATA_API\products.py", line 2173, in search_data_4
    conn = pyodbc.connect('Driver={SQL Server}; Server=192.168.8.21; uid=sa; pwd=1234;Database=QC; Trusted_Connection=No;',timeout=1)
           ^^^^^^^^^^^^^^^^^^^^^^^^^^^^^^^^^^^^^^^^^^^^^^^^^^^^^^^^^^^^^^^^^^^^^^^^^^^^^^^^^^^^^^^^^^^^^^^^^^^^^^^^^^^^^^^^^^^^^^^^^^
pyodbc.OperationalError: ('HYT00', '[HYT00] [Microsoft][ODBC SQL Server Driver]Login timeout expired (0) (SQLDriverConnect)')
 ---- search_data_4
-------------------Log----------------24/04/23-14:19:22
Traceback (most recent call last):
  File "C:\inetpub\wwwroot\WEB_DATA_API\CMM.py", line 162, in get_data
    conn = pyodbc.connect('Driver={SQL Server}; Server=192.168.8.21; uid=sa; pwd=1234;Database=QC; Trusted_Connection=No;',timeout=1)
           ^^^^^^^^^^^^^^^^^^^^^^^^^^^^^^^^^^^^^^^^^^^^^^^^^^^^^^^^^^^^^^^^^^^^^^^^^^^^^^^^^^^^^^^^^^^^^^^^^^^^^^^^^^^^^^^^^^^^^^^^^^
pyodbc.OperationalError: ('HYT00', '[HYT00] [Microsoft][ODBC SQL Server Driver]Login timeout expired (0) (SQLDriverConnect)')
 ---- cmm_data
-------------------Log----------------24/04/23-14:46:49
Traceback (most recent call last):
  File "C:\inetpub\wwwroot\WEB_DATA_API\CMM.py", line 162, in get_data
    conn = pyodbc.connect('Driver={SQL Server}; Server=192.168.8.21; uid=sa; pwd=1234;Database=QC; Trusted_Connection=No;',timeout=1)
           ^^^^^^^^^^^^^^^^^^^^^^^^^^^^^^^^^^^^^^^^^^^^^^^^^^^^^^^^^^^^^^^^^^^^^^^^^^^^^^^^^^^^^^^^^^^^^^^^^^^^^^^^^^^^^^^^^^^^^^^^^^
pyodbc.OperationalError: ('HYT00', '[HYT00] [Microsoft][ODBC SQL Server Driver]Login timeout expired (0) (SQLDriverConnect)')
 ---- cmm_data
-------------------Log----------------24/04/23-14:46:49
Traceback (most recent call last):
  File "C:\inetpub\wwwroot\WEB_DATA_API\CMM.py", line 162, in get_data
    conn = pyodbc.connect('Driver={SQL Server}; Server=192.168.8.21; uid=sa; pwd=1234;Database=QC; Trusted_Connection=No;',timeout=1)
           ^^^^^^^^^^^^^^^^^^^^^^^^^^^^^^^^^^^^^^^^^^^^^^^^^^^^^^^^^^^^^^^^^^^^^^^^^^^^^^^^^^^^^^^^^^^^^^^^^^^^^^^^^^^^^^^^^^^^^^^^^^
pyodbc.OperationalError: ('HYT00', '[HYT00] [Microsoft][ODBC SQL Server Driver]Login timeout expired (0) (SQLDriverConnect)')
 ---- cmm_data
-------------------Log----------------24/04/23-15:55:14
Traceback (most recent call last):
  File "C:\inetpub\wwwroot\WEB_DATA_API\CMM.py", line 162, in get_data
    conn = pyodbc.connect('Driver={SQL Server}; Server=192.168.8.21; uid=sa; pwd=1234;Database=QC; Trusted_Connection=No;',timeout=1)
           ^^^^^^^^^^^^^^^^^^^^^^^^^^^^^^^^^^^^^^^^^^^^^^^^^^^^^^^^^^^^^^^^^^^^^^^^^^^^^^^^^^^^^^^^^^^^^^^^^^^^^^^^^^^^^^^^^^^^^^^^^^
pyodbc.OperationalError: ('HYT00', '[HYT00] [Microsoft][ODBC SQL Server Driver]Login timeout expired (0) (SQLDriverConnect)')
 ---- cmm_data